Traceback (most recent call last):
  File "C:\Users\grego\anaconda3\envs\hausarbeit_wb4\lib\site-packages\jupyter_cache\executors\utils.py", line 58, in single_nb_execution
    executenb(
  File "C:\Users\grego\anaconda3\envs\hausarbeit_wb4\lib\site-packages\nbclient\client.py", line 1314, in execute
    return NotebookClient(nb=nb, resources=resources, km=km, **kwargs).execute()
  File "C:\Users\grego\anaconda3\envs\hausarbeit_wb4\lib\site-packages\jupyter_core\utils\__init__.py", line 165, in wrapped
    return loop.run_until_complete(inner)
  File "C:\Users\grego\anaconda3\envs\hausarbeit_wb4\lib\asyncio\base_events.py", line 649, in run_until_complete
    return future.result()
  File "C:\Users\grego\anaconda3\envs\hausarbeit_wb4\lib\site-packages\nbclient\client.py", line 709, in async_execute
    await self.async_execute_cell(
  File "C:\Users\grego\anaconda3\envs\hausarbeit_wb4\lib\site-packages\nbclient\client.py", line 1062, in async_execute_cell
    await self._check_raise_for_error(cell, cell_index, exec_reply)
  File "C:\Users\grego\anaconda3\envs\hausarbeit_wb4\lib\site-packages\nbclient\client.py", line 918, in _check_raise_for_error
    raise CellExecutionError.from_cell_and_msg(cell, exec_reply_content)
nbclient.exceptions.CellExecutionError: An error occurred while executing the following cell:
------------------
# Erstellung einer Einheitsganglinie fÃ¼r jeden Zeitschritt
runoff_df = pd.DataFrame(np.zeros(len(hourly_df)))
runoff_df.columns = ['Total Precip (mm)']
runoff_df.index = hourly_df.index.copy()
end_date = pd.to_datetime(runoff_df.index.values[-1]) + pd.DateOffset(hours=1)
max_distance = max(grouped_dists.index)
------------------


[1;31m---------------------------------------------------------------------------[0m
[1;31mNameError[0m                                 Traceback (most recent call last)
Cell [1;32mIn[37], line 6[0m
[0;32m      4[0m runoff_df[38;5;241m.[39mindex [38;5;241m=[39m hourly_df[38;5;241m.[39mindex[38;5;241m.[39mcopy()
[0;32m      5[0m end_date [38;5;241m=[39m pd[38;5;241m.[39mto_datetime(runoff_df[38;5;241m.[39mindex[38;5;241m.[39mvalues[[38;5;241m-[39m[38;5;241m1[39m]) [38;5;241m+[39m pd[38;5;241m.[39mDateOffset(hours[38;5;241m=[39m[38;5;241m1[39m)
[1;32m----> 6[0m max_distance [38;5;241m=[39m [38;5;28mmax[39m([43mgrouped_dists[49m[38;5;241m.[39mindex)

[1;31mNameError[0m: name 'grouped_dists' is not defined

